Workbook
Name Segment_DATE: #N/A
Name Segment_MODALITE: #N/A

Sheet Feuil2
A2: NUMDIST | B2: NOM_DIST | C2: Modalité | E2: STATUT | G2: DATES | H2: DESCRIPTION | J2: APPROVISIONNEMENT | L2: JPS DIEU MERCI
A3: 32928 | B3: KISANGANI - SHOP ESCALIER | C3: MPESA | E3: COMPTANT | G3: 46199 | H3: ACCREDITATION | J3: BANQUE | L3: Adresse | M3: N° 122, C/MBUNYA, Q. LUMUMBA, AV DELIBERATION
A4: 33056 | B4: KIVU - GRACIA SERVICE | C4: AIRTELMONEY | E4: CREDIT | G4: =G3+1 -> 46200 | H4: CREDIT | J4: RESEAU | L4: Telephone | M4: 0997785896 - 0810099378
A5: 34595 | B5: ETABLISSEMENT GAB KASINDI | C5: ORANGEMONEY | G5: =G4+1 -> 46201 | J5: CASH | L5: N° IMPOT | M5: A1516146S
A6: 34597 | B6: ETABLISSEMENT- JPS DM BIGO | C6: EQUITY | G6: =G5+1 -> 46202 | L6: ID NAT | M6: 4-93-N18362B
A7: 34598 | B7: ETABLISSEMENT JPS DM DURBA | C7: RAWBANK | G7: =G6+1 -> 46203 | L7: RCCM | M7: RCCM CD/BIA/RCCM-17-A-1193
A8: 36112 | B8: SUD KIVU - ETS AGRIPPINE | C8: TMB | G8: =G7+1 -> 46204 | L8: Coord Bank | M8: 1252-00584272701-19/CDF/RAWBANK/ETS MSO JPS DM
A9: 36272 | B9: BUNIA - JPS DM | C9: CADECO | G9: =G8+1 -> 46205
A10: 36429 | B10: BUNIA - VAD JPS DM | C10: CASH | G10: =G9+1 -> 46206
A11: 36430 | B11: Bunia - ETS BOTOAFINE | G11: =G10+1 -> 46207
A12: 36431 | B12: Isiro - MACAMPAGNE | G12: =G11+1 -> 46208
A13: 36433 | B13: BUNIA - CHEZ JUSTIN | G13: =G12+1 -> 46209
A14: 36434 | B14: BUNIA - ETS CALIFORNIE | G14: =G13+1 -> 46210
A15: 36532 | B15: BUNIA - EGIREX | G15: =G14+1 -> 46211
A16: 36710 | B16: BUNIA - BOUTIQUE JPS DM | G16: =G15+1 -> 46212
A17: 36711 | B17: MONGBWALU - ETS FSN | G17: =G16+1 -> 46213
A18: 41317 | B18: Bukavu - Ets JPS DM BUKAVU | G18: =G17+1 -> 46214
A19: 41614 | B19: KISANGANI - ETS WITHA | G19: =G18+1 -> 46215
A20: 42152 | B20: Bunia - Ets SKY | G20: =G19+1 -> 46216
A21: 42153 | B21: BUNIA - ETS SALEM | G21: =G20+1 -> 46217
A22: 42931 | B22: GOMA - VAD JPS DM | G22: =G21+1 -> 46218
... A236: 102551 | B236: BUNIA - ETS EVANGILE | G236: =G235+1 -> 46432
G237: =G236+1 -> 46433
G238: =G237+1 -> 46434
G239: =G238+1 -> 46435
G240: =G239+1 -> 46436
G241: =G240+1 -> 46437
G242: =G241+1 -> 46438
G243: =G242+1 -> 46439
G244: =G243+1 -> 46440
G245: =G244+1 -> 46441
G246: =G245+1 -> 46442
G247: =G246+1 -> 46443
G248: =G247+1 -> 46444
... G2767: =G2766+1 -> 48963

Sheet JOURNAL DES OPERATIONS
C2: =Feuil2!L2 -> JPS DIEU MERCI | G2: CGA
C3: Adresse | D3: =VLOOKUP($C3,Feuil2!$L$3:$M$8,2,0) -> N° 122, C/MBUNYA, Q. LUMUMBA, AV DELIBERATION | G3: STOCK INITIALE | H3: 109024970 | I3: STOCK ACTUEL | J3: =$H$5-TABLE_SYNTHESE[[#Totals],[SOMMES CREDITATION]] -> 78998651 | N3: SYNTESE | R3: PASSWORD: JPS2026
C4: Telephone | D4: =VLOOKUP($C4,Feuil2!$L$3:$M$8,2,0) -> 0997785896 - 0810099378 | M4: MODALITE | N4: SOMMES CREDITATION | O4: SOMMES APROVISIONNEMENT | P4: SOMME PAR MODALITE
C5: N° IMPOT | D5: =VLOOKUP($C5,Feuil2!$L$3:$M$8,2,0) -> A1516146S | H5: =H3+TABLE_SYNTHESE[[#Totals],[SOMMES APROVISIONNEMENT]] -> 787888924 | M5: MPESA | N5: =SUMIF('JOURNAL DES OPERATIONS'!$G$12:$I$1595,$M5,'JOURNAL DES OPERATIONS'!$H$12:$H$1595) -> 80328900 | O5: =SUMIF('JOURNAL DES OPERATIONS'!$G$12:$I$1595,$M5,'JOURNAL DES OPERATIONS'!$I$12:$I$1595) -> 0 | P5: =SUM(N5:O5) -> 80328900
C6: ID NAT | D6: =VLOOKUP($C6,Feuil2!$L$3:$M$8,2,0) -> 4-93-N18362B | M6: CASH | N6: =SUMIF('JOURNAL DES OPERATIONS'!$G$12:$I$1595,$M6,'JOURNAL DES OPERATIONS'!$H$12:$H$1595) -> 171706465 | O6: =SUMIF('JOURNAL DES OPERATIONS'!$G$12:$I$1595,$M6,'JOURNAL DES OPERATIONS'!$I$12:$I$1595) -> 0 | P6: =SUM(N6:O6) -> 171706465
C7: RCCM | D7: =VLOOKUP($C7,Feuil2!$L$3:$M$8,2,0) -> RCCM CD/BIA/RCCM-17-A-1193 | M7: AIRTELMONEY | N7: =SUMIF('JOURNAL DES OPERATIONS'!$G$12:$I$1595,$M7,'JOURNAL DES OPERATIONS'!$H$12:$H$1595) -> 101069527 | O7: =SUMIF('JOURNAL DES OPERATIONS'!$G$12:$I$1595,$M7,'JOURNAL DES OPERATIONS'!$I$12:$I$1595) -> 0 | P7: =SUM(N7:O7) -> 101069527
C8: Coord Bank | D8: =VLOOKUP($C8,Feuil2!$L$3:$M$8,2,0) -> 1252-00584272701-19/CDF/RAWBANK/ETS MSO JPS DM | M8: ORANGEMONEY | N8: =SUMIF('JOURNAL DES OPERATIONS'!$G$12:$I$1595,$M8,'JOURNAL DES OPERATIONS'!$H$12:$H$1595) -> 48689400 | O8: =SUMIF('JOURNAL DES OPERATIONS'!$G$12:$I$1595,$M8,'JOURNAL DES OPERATIONS'!$I$12:$I$1595) -> 0 | P8: =SUM(N8:O8) -> 48689400
F9: JOURNAL OPERATION JPS | M9: EQUITY | N9: =SUMIF('JOURNAL DES OPERATIONS'!$G$12:$I$1595,$M9,'JOURNAL DES OPERATIONS'!$H$12:$H$1595) -> 249410831 | O9: =SUMIF('JOURNAL DES OPERATIONS'!$G$12:$I$1595,$M9,'JOURNAL DES OPERATIONS'!$I$12:$I$1595) -> 352613454 | P9: =SUM(N9:O9) -> 602024285
M10: RAWBANK | N10: =SUMIF('JOURNAL DES OPERATIONS'!$G$12:$I$1595,$M10,'JOURNAL DES OPERATIONS'!$H$12:$H$1595) -> 35249200 | O10: =SUMIF('JOURNAL DES OPERATIONS'!$G$12:$I$1595,$M10,'JOURNAL DES OPERATIONS'!$I$12:$I$1595) -> 326250500 | P10: =SUM(N10:O10) -> 361499700
C11: DATE | D11: NIM_DIST | E11: NOM_DISTR | F11: DESCRIPTION | G11: MODALITE | H11: CREDITATION | I11: APPROVISIONNMENT | J11: STATUT | K11: RESPONSABLE2 | M11: TMB | N11: =SUMIF('JOURNAL DES OPERATIONS'!$G$12:$I$1595,$M11,'JOURNAL DES OPERATIONS'!$H$12:$H$1595) -> 6415500 | O11: =SUMIF('JOURNAL DES OPERATIONS'!$G$12:$I$1595,$M11,'JOURNAL DES OPERATIONS'!$I$12:$I$1595) -> 0 | P11: =SUM(N11:O11) -> 6415500
C12: 46202 | D12: 95820 | E12: =IFERROR(VLOOKUP($D12,NUMDIST[],2,FALSE),"DA Non trouvéé") -> MONGWALU - MAISON INTEMPORELLE | F12: CREDITATION REABONNEMENT | G12: MPESA | H12: 270700 | I12: 0 | J12: COMPTANT | K12: JULIENNE | M12: CADECO | N12: =SUMIF('JOURNAL DES OPERATIONS'!$G$12:$I$1595,$M12,'JOURNAL DES OPERATIONS'!$H$12:$H$1595) -> 16020450 | O12: =SUMIF('JOURNAL DES OPERATIONS'!$G$12:$I$1595,$M12,'JOURNAL DES OPERATIONS'!$I$12:$I$1595) -> 0 | P12: =SUM(N12:O12) -> 16020450
C13: 46202 | D13: 34597 | E13: =IFERROR(VLOOKUP($D13,NUMDIST[],2,FALSE),"DA Non trouvéé") -> ETABLISSEMENT- JPS DM BIGO | F13: CREDITATION REABONNEMENT | G13: EQUITY | H13: 162000 | I13: 0 | J13: COMPTANT | K13: JULIENNE | N13: =SUM(N5:N12) -> 708890273 | O13: =SUBTOTAL(109,TABLE_SYNTHESE[SOMMES APROVISIONNEMENT]) -> 678863954 | P13: =SUBTOTAL(109,TABLE_SYNTHESE[SOMME PAR MODALITE]) -> 1387754227
C14: 46202 | D14: 34597 | E14: =IFERROR(VLOOKUP($D14,NUMDIST[],2,FALSE),"DA Non trouvéé") -> ETABLISSEMENT- JPS DM BIGO | F14: CREDITATION REABONNEMENT | G14: TMB | H14: 2185500 | I14: 0 | J14: COMPTANT | K14: JULIENNE
C15: 46202 | D15: 92122 | E15: =IFERROR(VLOOKUP($D15,NUMDIST[],2,FALSE),"DA Non trouvéé") -> KISANGANI - MONT GOLOGOTA | F15: CREDITATION REABONNEMENT | G15: AIRTELMONEY | H15: 376000 | I15: 0 | J15: COMPTANT | K15: JULIENNE
C16: 46202 | D16: 85827 | E16: =IFERROR(VLOOKUP($D16,NUMDIST[],2,FALSE),"DA Non trouvéé") -> KISANGANI - SHOP LA GRACE | F16: CREDITATION REABONNEMENT | G16: EQUITY | H16: 693250 | I16: 0 | J16: COMPTANT | K16: JULIENNE
C17: 46202 | D17: 59057 | E17: =IFERROR(VLOOKUP($D17,NUMDIST[],2,FALSE),"DA Non trouvéé") -> ITURI - ETS BJSE | F17: CREDITATION REABONNEMENT | G17: CASH | H17: 1502500 | I17: 0 | J17: COMPTANT | K17: JULIENNE
C18: 46202 | D18: 42152 | E18: =IFERROR(VLOOKUP($D18,NUMDIST[],2,FALSE),"DA Non trouvéé") -> Bunia - Ets SKY | F18: CREDITATION REABONNEMENT | G18: CADECO | H18: 1629000 | I18: 0 | J18: COMPTANT | K18: JULIENNE
C19: 46202 | D19: 99337 | E19: =IFERROR(VLOOKUP($D19,NUMDIST[],2,FALSE),"DA Non trouvéé") -> ISIRO - SHOP CHARA HOUSE | F19: CREDITATION REABONNEMENT | G19: EQUITY | H19: 2385250 | I19: 0 | J19: COMPTANT | K19: JULIENNE
C20: 46202 | D20: 90134 | E20: =IFERROR(VLOOKUP($D20,NUMDIST[],2,FALSE),"DA Non trouvéé") -> KISANGANI - ETS SOLUTION PLUS | F20: CREDITATION REABONNEMENT | G20: MPESA | H20: 300000 | I20: 0 | J20: COMPTANT | K20: JULIENNE
C21: 46202 | D21: 36710 | E21: =IFERROR(VLOOKUP($D21,NUMDIST[],2,FALSE),"DA Non trouvéé") -> BUNIA - BOUTIQUE JPS DM | F21: CREDITATION REABONNEMENT | G21: CASH | H21: 3485100 | I21: 0 | J21: CREDIT | K21: JULIENNE
C22: 46202 | D22: 87500 | E22: =IFERROR(VLOOKUP($D22,NUMDIST[],2,FALSE),"DA Non trouvéé") -> BUNIA - ETS DIEU MERCI | F22: CREDITATION REABONNEMENT | G22: CASH | H22: 141000 | I22: 0 | J22: COMPTANT | K22: JULIENNE
C23: 46202 | D23: 104929 | E23: =IFERROR(VLOOKUP($D23,NUMDIST[],2,FALSE),"DA Non trouvéé") -> KISANGANI - THEODOR BUSINESS | F23: CREDITATION REABONNEMENT | G23: MPESA | H23: 164500 | I23: 0 | J23: COMPTANT | K23: JULIENNE
C24: 46202 | D24: 71084 | E24: =IFERROR(VLOOKUP($D24,NUMDIST[],2,FALSE),"DA Non trouvéé") -> DURBA - Ets HUSSUMA BUSINESS | F24: CREDITATION REABONNEMENT | G24: EQUITY | H24: 11916850 | I24: 0 | J24: COMPTANT | K24: JULIENNE
C25: 46202 | D25: 85837 | E25: =IFERROR(VLOOKUP($D25,NUMDIST[],2,FALSE),"DA Non trouvéé") -> BENI - SHOP ESPERANCE | F25: CREDITATION REABONNEMENT | G25: CASH | H25: 470000 | I25: 0 | J25: CREDIT | K25: JULIENNE
... C50: 46202 | D50: 87503 | E50: =IFERROR(VLOOKUP($D50,NUMDIST[],2,FALSE),"DA Non trouvéé") -> BUKAVU - ETS DIEU EST GRAND | F50: CREDITATION REABONNEMENT | G50: CASH | H50: 352500 | I50: 0 | J50: CREDIT | K50: JULIENNE
C51: 46203 | D51: 34597 | E51: =IFERROR(VLOOKUP($D51,NUMDIST[],2,FALSE),"DA Non trouvéé") -> ETABLISSEMENT- JPS DM BIGO | F51: CREDITATION REABONNEMENT | G51: EQUITY | H51: 1645000 | I51: 0 | J51: COMPTANT
C52: 46203 | D52: 90176 | E52: =IFERROR(VLOOKUP($D52,NUMDIST[],2,FALSE),"DA Non trouvéé") -> BUNIA - SHOP MATATA | F52: CREDITATION REABONNEMENT | G52: EQUITY | H52: 470000 | I52: 0 | J52: COMPTANT
C53: 46203 | D53: 91775 | E53: =IFERROR(VLOOKUP($D53,NUMDIST[],2,FALSE),"DA Non trouvéé") -> MAHAGI - MAISON DIGITAL | F53: CREDITATION REABONNEMENT | G53: RAWBANK | H53: 799500 | I53: 0 | J53: COMPTANT
C54: 46203 | D54: 55350 | E54: =IFERROR(VLOOKUP($D54,NUMDIST[],2,FALSE),"DA Non trouvéé") -> OICHA - CLINIQUE ORDINATEURS | F54: CREDITATION REABONNEMENT | G54: AIRTELMONEY | H54: 352500 | I54: 0 | J54: COMPTANT
C55: 46203 | D55: 95823 | E55: =IFERROR(VLOOKUP($D55,NUMDIST[],2,FALSE),"DA Non trouvéé") -> BUNIA - ETS CANAL BIA | F55: CREDITATION REABONNEMENT | G55: CASH | H55: 235000 | I55: 0 | J55: CREDIT
C56: 46203 | D56: 100652 | E56: =IFERROR(VLOOKUP($D56,NUMDIST[],2,FALSE),"DA Non trouvéé") -> BUNIA - ETS COURAGE IT | F56: CREDITATION REABONNEMENT | G56: MPESA | H56: 470000 | I56: 0 | J56: COMPTANT
C57: 46203 | D57: 90172 | E57: =IFERROR(VLOOKUP($D57,NUMDIST[],2,FALSE),"DA Non trouvéé") -> BUNIA - SHOP DOXA | F57: CREDITATION REABONNEMENT | G57: MPESA | H57: 500000 | I57: 0 | J57: COMPTANT
C58: 46203 | D58: 99337 | E58: =IFERROR(VLOOKUP($D58,NUMDIST[],2,FALSE),"DA Non trouvéé") -> ISIRO - SHOP CHARA HOUSE | F58: CREDITATION REABONNEMENT | G58: EQUITY | H58: 1359500 | I58: 0 | J58: COMPTANT
C59: 46203 | D59: 91770 | E59: =IFERROR(VLOOKUP($D59,NUMDIST[],2,FALSE),"DA Non trouvéé") -> BUKAVU - MAISON JULIEN BS | F59: CREDITATION REABONNEMENT | G59: EQUITY | H59: 470000 | I59: 0 | J59: COMPTANT
C60: 46203 | D60: 36710 | E60: =IFERROR(VLOOKUP($D60,NUMDIST[],2,FALSE),"DA Non trouvéé") -> BUNIA - BOUTIQUE JPS DM | F60: CREDITATION REABONNEMENT | G60: CASH | H60: 4948500 | I60: 0 | J60: CREDIT
C61: 46203 | D61: 90174 | E61: =IFERROR(VLOOKUP($D61,NUMDIST[],2,FALSE),"DA Non trouvéé") -> MAHAGI - ETS JACQUES PLUS | F61: CREDITATION REABONNEMENT | G61: MPESA | H61: 260000 | I61: 0 | J61: COMPTANT
C62: 46203 | D62: 103992 | E62: =IFERROR(VLOOKUP($D62,NUMDIST[],2,FALSE),"DA Non trouvéé") -> ETABLISEMENT ESPOIR BUSINESS | F62: CREDITATION REABONNEMENT | G62: AIRTELMONEY | H62: 705000 | I62: 0 | J62: COMPTANT
... C85: 46203 | D85: 71090 | E85: =IFERROR(VLOOKUP($D85,NUMDIST[],2,FALSE),"DA Non trouvéé") -> SHOP JULUX | F85: CREDITATION REABONNEMENT | G85: CASH | H85: 2350000 | I85: 0 | J85: CREDIT
C86: 01/07/2026 | D86: 95823 | E86: =IFERROR(VLOOKUP($D86,NUMDIST[],2,FALSE),"DA Non trouvéé") -> BUNIA - ETS CANAL BIA | F86: CREDITATION REABONNEMENT | G86: CASH | H86: 352500 | I86: 0 | J86: COMPTANT | K86: JULIENNE
C87: 01/07/2026 | D87: 54298 | E87: =IFERROR(VLOOKUP($D87,NUMDIST[],2,FALSE),"DA Non trouvéé") -> KIVU - SHOP SATELLITE | F87: CREDITATION REABONNEMENT | G87: AIRTELMONEY | H87: 587500 | I87: 0 | J87: COMPTANT | K87: JULIENNE
...

Sheet Feuil1
H2: VENTE REEL DU JOURS: | J2: 8283900
H3: VENTE REEL DU JOURS: | J3: 17226175
B4: Colonne1 | C4: Colonne2 | D4: USD | E4: Colonne3 | F4: CDF | H4: VENTE DU 26 ET 27 | J4: 13995800
A5: VENDREDI | B5: AIRTEL | C5: 787 | D5: USD | E5: 0
B6: CADECO | C6: 100 | D6: USD | E6: 650000 | F6: CDF
B7: CASH | C7: 0 | E7: 2566000 | F7: CDF
B8: EQUITY | C8: 800 | D8: USD | E8: 88000 | F8: CDF | H8: SOLDE FIN JOURNEE: 79 343 578 CDF
B9: MPESA | C9: 0 | E9: 200000 | F9: CDF | H9: APPROVISIONNEMENT COMPTE: 10 100 USD
B10: CREDIT | C10: 0 | E10: 0
B11: RAWBANK | C11: 347 | D11: USD | E11: 0
A13: LUNDI | B13: Colonne1 | C13: Colonne2 | D13: USD | E13: Colonne3 | F13: CDF | H13: SOLDE FIN JOURNEE: 48 121 603 CDF
B14: AIRTEL | C14: 832 | D14: USD | E14: 200000 | F14: CDF
B15: CASH | C15: 300 | D15: USD | E15: 2017600 | F15: CDF | I15: {=SUM(Tableau9[Colonne3],Tableau9[Colonne2]*2350)} -> 8283900
B16: CREDIT | C16: 2300 | D16: USD | E16: 0
B17: CADECO | C17: 0 | E17: 0
B18: EQUITY | C18: 1480 | D18: USD | E18: 0
B19: MPESA | C19: 0 | E19: 0
B20: MPESA | C20: 100 | D20: USD | E20: 0 | I20: {=SUM(Tableau11[Colonne3]+Tableau11[Colonne2]*2350)} -> 13995800
A21: SAM ² DIM
B22: Colonne1 | C22: Colonne2 | D22: USD | E22: Colonne3 | F22: CDF
B23: AIRTEL | C23: 634 | D23: USD | E23: 0
B24: CASH | C24: 500 | D24: USD | E24: 2601700 | F24: CDF
B25: CREDIT | C25: 1100 | D25: USD | E25: 5000000 | F25: CDF
B26: EQUITY | C26: 1091.5 | D26: USD | E26: 0
B27: MPSA | C27: 403 | D27: USD | E27: 0
B28: CADECO | C28: 0 | E28: 0 | I28: {=SUM(Tableau12[Colonne3]+(Tableau12[Colonne2]*2350))} -> 17226175
B29: RAWBANK | C29: 220 | D29: USD | E29: 345500 | F29: CDF
B30: SOLDE FIN JOURNEE: | D30: 62 117 403 CDF

Sheet SYTHESE JOURNALIER
B1: DU 24 AU 27/7/26 | D1: MARDI 28/7/2026 | F1: MERCREDI 29/7/2026 | H1: JEUDI 30/7/2026 | J1: VENDREDI 31/7/2026 | L1: SAMEDI 1/8/2026 | N1: 46237 | P1: 46238 | R1: 46239 | T1: 46240 | V1: 46241 | X1: 46242 | Z1: 46243 | AB1: 46244 | AD1: 46245 | AF1: 46246 | AH1: 46247 | AJ1: 46248 | AL1: 46249 | AN1: 46250 | AP1: 46251 | AR1: 46252 | AT1: 46253 | AV1: 46254 | AX1: 46255 | AZ1: 46256 | BB1: 46257 | BD1: 46258 | BF1: 46259 | BH1: 46260 | BJ1: 46261 | BL1: 46262 | BN1: 46263 | BP1: 46264 | BR1: 46265 | BT1: 46266 | BV1: 46267 | BX1: 46268 | BZ1: 46269 | CB1: 46270 | CD1: 46271 | CF1: 46272
A2: Colonne1 | B2: CDF | C2: USD | D2: CDF2 | E2: USD3 | F2: CDF4 | G2: USD5 | H2: CDF6 | I2: USD7 | J2: CDF7 | K2: USD8 | L2: CDF8 | M2: USD9 | N2: CDF9 | O2: USD10 | P2: CDF10 | Q2: USD11 | R2: CDF11 | S2: USD12 | T2: CDF12 | U2: USD13 | V2: CDF13 | W2: USD14 | X2: CDF14 | Y2: USD15 | Z2: CDF15 | AA2: USD16 | AB2: CDF16 | AC2: USD17 | AD2: CDF17 | AE2: USD18 | AF2: CDF18 | AG2: USD19 | AH2: CDF19 | AI2: USD20 | AJ2: CDF20 | AK2: USD21 | AL2: CDF21 | AM2: USD22 | AN2: CDF22 | AO2: USD23 | AP2: CDF23 | AQ2: USD24 | AR2: CDF24 | AS2: USD25 | AT2: CDF25 | AU2: USD26 | AV2: CDF26 | AW2: USD27 | AX2: CDF27 | AY2: USD28 | AZ2: CDF28 | BA2: USD29 | BB2: CDF29 | BC2: USD30 | BD2: CDF30 | BE2: USD31 | BF2: CDF31 | BG2: USD32 | BH2: CDF32 | BI2: USD33 | BJ2: CDF33 | BK2: USD34 | BL2: CDF34 | BM2: USD35 | BN2: CDF35 | BO2: USD36 | BP2: CDF36 | BQ2: USD37 | BR2: CDF37 | BS2: USD38 | BT2: CDF38 | BU2: USD39 | BV2: CDF39 | BW2: USD40 | BX2: CDF40 | BY2: USD41 | BZ2: CDF41 | CA2: USD42 | CB2: CDF42 | CC2: USD43 | CD2: CDF43 | CE2: USD44 | CF2: CDF44 | CG2: USD45
A3: AIRTEL | B3: =SUMIF(Feuil1!$B$5:$F$29,Tableau1[[#This Row],[Colonne1]],Feuil1!$E$5:$E$29) -> 200000 | C3: =SUMIF(Feuil1!$B$5:$F$29,Tableau1[[#This Row],[Colonne1]],Feuil1!$C$5:$C$29) -> 2253 | D3: 0 | E3: 200 | F3: 200000 | G3: 1163.32 | H3: 0 | I3: 650 | J3: 300000 | K3: 1494.5 | M3: 1951.5
A4: CADECO | B4: =SUMIF(Feuil1!$B$5:$F$29,Tableau1[[#This Row],[Colonne1]],Feuil1!$E$5:$E$29) -> 650000 | C4: =SUMIF(Feuil1!$B$5:$F$29,Tableau1[[#This Row],[Colonne1]],Feuil1!$C$5:$C$29) -> 100 | D4: 600000 | E4: 150 | H4: 550000 | I4: 90
A5: CASH | B5: =SUMIF(Feuil1!$B$5:$F$29,Tableau1[[#This Row],[Colonne1]],Feuil1!$E$5:$E$29) -> 7185300 | C5: =SUMIF(Feuil1!$B$5:$F$29,Tableau1[[#This Row],[Colonne1]],Feuil1!$C$5:$C$29) -> 800 | D5: 2370400 | E5: 160 | F5: 2247550 | G5: 120 | H5: 2901400 | I5: 200 | J5: 3366800 | K5: 970 | L5: 3056600 | M5: 430
A6: CREDIT | B6: =SUMIF(Feuil1!$B$5:$F$29,Tableau1[[#This Row],[Colonne1]],Feuil1!$E$5:$E$29) -> 5000000 | C6: =SUMIF(Feuil1!$B$5:$F$29,Tableau1[[#This Row],[Colonne1]],Feuil1!$C$5:$C$29) -> 3400 | D6: 0 | E6: 355 | F6: 0 | G6: 600 | H6: 0 | I6: 300 | K6: 500 | L6: 0 | M6: 2100
A7: EQUITY | B7: =SUMIF(Feuil1!$B$5:$F$29,Tableau1[[#This Row],[Colonne1]],Feuil1!$E$5:$E$29) -> 88000 | C7: =SUMIF(Feuil1!$B$5:$F$29,Tableau1[[#This Row],[Colonne1]],Feuil1!$C$5:$C$29) -> 3371.5 | D7: 0 | E7: 1130 | F7: 2585000 | G7: 3618.3 | H7: 0 | I7: 2473 | J7: 2083000 | K7: 1190 | L7: 619500 | M7: 5139
A8: MPSA | B8: =SUMIF(Feuil1!$B$5:$F$29,Tableau1[[#This Row],[Colonne1]],Feuil1!$E$5:$E$29) -> 0 | C8: =SUMIF(Feuil1!$B$5:$F$29,Tableau1[[#This Row],[Colonne1]],Feuil1!$C$5:$C$29) -> 403 | D8: 0 | E8: 0 | F8: 472000 | G8: 200 | H8: 0 | I8: 0 | J8: 1145000 | K8: 200 | L8: 270000 | M8: 720
A9: RAWBANK | B9: =SUMIF(Feuil1!$B$5:$F$29,Tableau1[[#This Row],[Colonne1]],Feuil1!$E$5:$E$29) -> 345500 | C9: =SUMIF(Feuil1!$B$5:$F$29,Tableau1[[#This Row],[Colonne1]],Feuil1!$C$5:$C$29) -> 567 | D9: 400000 | E9: 635 | F9: 0 | G9: 351 | J9: 727600 | K9: 913 | L9: 280000 | M9: 400
A10: TMB | B10: =SUMIF(Feuil1!$B$5:$F$29,Tableau1[[#This Row],[Colonne1]],Feuil1!$E$5:$E$29) -> 0 | C10: =SUMIF(Feuil1!$B$5:$F$29,Tableau1[[#This Row],[Colonne1]],Feuil1!$C$5:$C$29) -> 0 | E10: 0
B11: =SUBTOTAL(109,B3:B10) -> 13468800 | C11: =SUBTOTAL(109,C3:C10) -> 10894.5 | D11: =SUBTOTAL(109,D3:D10) -> 3370400 | E11: =SUBTOTAL(109,E3:E10) -> 2630 | F11: =SUBTOTAL(109,F3:F10) -> 5504550 | G11: =SUBTOTAL(109,G3:G10) -> 6052.62 | H11: =SUBTOTAL(109,H3:H10) -> 3451400 | I11: =SUBTOTAL(109,I3:I10) -> 3713 | ... CG11: =SUBTOTAL(109,CG3:CG10) -> 0
B12: =B11+(C11*2350) -> 39070875 | D12: =D11+(E11*2350) -> 9550900 | F12: =F11+(G11*2350) -> 19728207 | H12: =H11+(I11*2350) -> 12176950 | J12: =J11+(K11*2350) -> 20001025 | L12: =L11+(M11*2350) -> 29466275 | N12: =N11+(O11*2350) -> 0 | P12: =P11+(Q11*2350) -> 0 | R12: =R11+(S11*2350) -> 0 | T12: =T11+(U11*2350) -> 0 | V12: =V11+(W11*2350) -> 0 | X12: =X11+(Y11*2350) -> 0 | Z12: =Z11+(AA11*2350) -> 0 | AB12: =AB11+(AC11*2350) -> 0 | AD12: =AD11+(AE11*2350) -> 0 | AF12: =AF11+(AG11*2350) -> 0 | AH12: =AH11+(AI11*2350) -> 0 | AJ12: =AJ11+(AK11*2350) -> 0 | AL12: =AL11+(AM11*2350) -> 0 | AN12: =AN11+(AO11*2350) -> 0 | AP12: =AP11+(AQ11*2350) -> 0 | AR12: =AR11+(AS11*2350) -> 0 | AT12: =AT11+(AU11*2350) -> 0 | AV12: =AV11+(AW11*2350) -> 0 | AX12: =AX11+(AY11*2350) -> 0 | AZ12: =AZ11+(BA11*2350) -> 0 | BB12: =BB11+(BC11*2350) -> 0 | BD12: =BD11+(BE11*2350) -> 0 | BF12: =BF11+(BG11*2350) -> 0 | BH12: =BH11+(BI11*2350) -> 0 | BJ12: =BJ11+(BK11*2350) -> 0 | BL12: =BL11+(BM11*2350) -> 0 | BN12: =BN11+(BO11*2350) -> 0 | BP12: =BP11+(BQ11*2350) -> 0 | BR12: =BR11+(BS11*2350) -> 0 | BT12: =BT11+(BU11*2350) -> 0 | BV12: =BV11+(BW11*2350) -> 0 | BX12: =BX11+(BY11*2350) -> 0 | BZ12: =BZ11+(CA11*2350) -> 0 | CB12: =CB11+(CC11*2350) -> 0 | CD12: =CD11+(CE11*2350) -> 0 | CF12: =CF11+(CG11*2350) -> 0
A15: AIRTEL | C15: =B3+(C3*2350) -> 5494550 | E15: =D3+(E3*2350) -> 470000 | G15: =F3+(G3*2350) -> 2933802 | I15: =H3+(I3*2350) -> 1527500 | K15: =J3+(K3*2350) -> 3812075 | M15: =L3+(M3*2350) -> 4586025 | O15: =N3+(O3*2350) -> 0 | Q15: =P3+(Q3*2350) -> 0 | S15: =R3+(S3*2350) -> 0 | U15: =T3+(U3*2350) -> 0 | W15: =V3+(W3*2350) -> 0 | Y15: =X3+(Y3*2350) -> 0 | AA15: =Z3+(AA3*2350) -> 0 | AC15: =AB3+(AC3*2350) -> 0 | AE15: =AD3+(AE3*2350) -> 0 | AG15: =AF3+(AG3*2350) -> 0 | AI15: =AH3+(AI3*2350) -> 0 | AK15: =AJ3+(AK3*2350) -> 0 | AM15: =AL3+(AM3*2350) -> 0 | AO15: =AN3+(AO3*2350) -> 0 | AQ15: =AP3+(AQ3*2350) -> 0 | AS15: =AR3+(AS3*2350) -> 0 | AU15: =AT3+(AU3*2350) -> 0 | AW15: =AV3+(AW3*2350) -> 0 | AY15: =AX3+(AY3*2350) -> 0 | BA15: =AZ3+(BA3*2350) -> 0 | BC15: =BB3+(BC3*2350) -> 0 | BE15: =BD3+(BE3*2350) -> 0 | BG15: =BF3+(BG3*2350) -> 0 | BI15: =BH3+(BI3*2350) -> 0 | BK15: =BJ3+(BK3*2350) -> 0 | BM15: =BL3+(BM3*2350) -> 0 | BO15: =BN3+(BO3*2350) -> 0 | BQ15: =BP3+(BQ3*2350) -> 0 | BS15: =BR3+(BS3*2350) -> 0 | BU15: =BT3+(BU3*2350) -> 0 | BW15: =BV3+(BW3*2350) -> 0 | BY15: =BX3+(BY3*2350) -> 0 | CA15: =BZ3+(CA3*2350) -> 0 | CC15: =CB3+(CC3*2350) -> 0 | CE15: =CD3+(CE3*2350) -> 0 | CG15: =CF3+(CG3*2350) -> 0
A16: CADECO | C16: =B4+(C4*2350) -> 885000 | E16: =D5+(E5*2350) -> 2746400 | G16: =F5+(G5*2350) -> 2529550 | I16: =H5+(I5*2350) -> 3371400 | K16: =J5+(K5*2350) -> 5646300 | M16: =L5+(M5*2350) -> 4067100 | O16: =N5+(O5*2350) -> 0 | Q16: =P5+(Q5*2350) -> 0 | S16: =R5+(S5*2350) -> 0 | U16: =T5+(U5*2350) -> 0 | W16: =V5+(W5*2350) -> 0 | Y16: =X5+(Y5*2350) -> 0 | AA16: =Z5+(AA5*2350) -> 0 | AC16: =AB5+(AC5*2350) -> 0 | AE16: =AD5+(AE5*2350) -> 0 | AG16: =AF5+(AG5*2350) -> 0 | AI16: =AH5+(AI5*2350) -> 0 | AK16: =AJ5+(AK5*2350) -> 0 | AM16: =AL5+(AM5*2350) -> 0 | AO16: =AN5+(AO5*2350) -> 0 | AQ16: =AP5+(AQ5*2350) -> 0 | AS16: =AR5+(AS5*2350) -> 0 | AU16: =AT5+(AU5*2350) -> 0 | AW16: =AV5+(AW5*2350) -> 0 | AY16: =AX5+(AY5*2350) -> 0 | BA16: =AZ5+(BA5*2350) -> 0 | BC16: =BB5+(BC5*2350) -> 0 | BE16: =BD5+(BE5*2350) -> 0 | BG16: =BF5+(BG5*2350) -> 0 | BI16: =BH5+(BI5*2350) -> 0 | BK16: =BJ5+(BK5*2350) -> 0 | BM16: =BL5+(BM5*2350) -> 0 | BO16: =BN5+(BO5*2350) -> 0 | BQ16: =BP5+(BQ5*2350) -> 0 | BS16: =BR5+(BS5*2350) -> 0 | BU16: =BT5+(BU5*2350) -> 0 | BW16: =BV5+(BW5*2350) -> 0 | BY16: =BX5+(BY5*2350) -> 0 | CA16: =BZ5+(CA5*2350) -> 0 | CC16: =CB5+(CC5*2350) -> 0 | CE16: =CD5+(CE5*2350) -> 0 | CG16: =CF5+(CG5*2350) -> 0
A17: CASH | C17: =B5+(C5*2350) -> 9065300 | E17: =D6+(E6*2350) -> 834250 | G17: =F6+(G6*2350) -> 1410000 | I17: =H6+(I6*2350) -> 705000 | K17: =J6+(K6*2350) -> 1175000 | M17: =L6+(M6*2350) -> 4935000 | O17: =N6+(O6*2350) -> 0 | Q17: =P6+(Q6*2350) -> 0 | S17: =R6+(S6*2350) -> 0 | U17: =T6+(U6*2350) -> 0 | W17: =V6+(W6*2350) -> 0 | Y17: =X6+(Y6*2350) -> 0 | AA17: =Z6+(AA6*2350) -> 0 | AC17: =AB6+(AC6*2350) -> 0 | AE17: =AD6+(AE6*2350) -> 0 | AG17: =AF6+(AG6*2350) -> 0 | AI17: =AH6+(AI6*2350) -> 0 | AK17: =AJ6+(AK6*2350) -> 0 | AM17: =AL6+(AM6*2350) -> 0 | AO17: =AN6+(AO6*2350) -> 0 | AQ17: =AP6+(AQ6*2350) -> 0 | AS17: =AR6+(AS6*2350) -> 0 | AU17: =AT6+(AU6*2350) -> 0 | AW17: =AV6+(AW6*2350) -> 0 | AY17: =AX6+(AY6*2350) -> 0 | BA17: =AZ6+(BA6*2350) -> 0 | BC17: =BB6+(BC6*2350) -> 0 | BE17: =BD6+(BE6*2350) -> 0 | BG17: =BF6+(BG6*2350) -> 0 | BI17: =BH6+(BI6*2350) -> 0 | BK17: =BJ6+(BK6*2350) -> 0 | BM17: =BL6+(BM6*2350) -> 0 | BO17: =BN6+(BO6*2350) -> 0 | BQ17: =BP6+(BQ6*2350) -> 0 | BS17: =BR6+(BS6*2350) -> 0 | BU17: =BT6+(BU6*2350) -> 0 | BW17: =BV6+(BW6*2350) -> 0 | BY17: =BX6+(BY6*2350) -> 0 | CA17: =BZ6+(CA6*2350) -> 0 | CC17: =CB6+(CC6*2350) -> 0 | CE17: =CD6+(CE6*2350) -> 0 | CG17: =CF6+(CG6*2350) -> 0
A18: CREDIT | C18: =B6+(C6*2350) -> 12990000 | E18: =D7+(E7*2350) -> 2655500 | G18: =F7+(G7*2350) -> 11088005 | I18: =H7+(I7*2350) -> 5811550 | K18: =J7+(K7*2350) -> 4879500 | M18: =L7+(M7*2350) -> 12696150 | O18: =N7+(O7*2350) -> 0 | Q18: =P7+(Q7*2350) -> 0 | S18: =R7+(S7*2350) -> 0 | U18: =T7+(U7*2350) -> 0 | W18: =V7+(W7*2350) -> 0 | Y18: =X7+(Y7*2350) -> 0 | AA18: =Z7+(AA7*2350) -> 0 | AC18: =AB7+(AC7*2350) -> 0 | AE18: =AD7+(AE7*2350) -> 0 | AG18: =AF7+(AG7*2350) -> 0 | AI18: =AH7+(AI7*2350) -> 0 | AK18: =AJ7+(AK7*2350) -> 0 | AM18: =AL7+(AM7*2350) -> 0 | AO18: =AN7+(AO7*2350) -> 0 | AQ18: =AP7+(AQ7*2350) -> 0 | AS18: =AR7+(AS7*2350) -> 0 | AU18: =AT7+(AU7*2350) -> 0 | AW18: =AV7+(AW7*2350) -> 0 | AY18: =AX7+(AY7*2350) -> 0 | BA18: =AZ7+(BA7*2350) -> 0 | BC18: =BB7+(BC7*2350) -> 0 | BE18: =BD7+(BE7*2350) -> 0 | BG18: =BF7+(BG7*2350) -> 0 | BI18: =BH7+(BI7*2350) -> 0 | BK18: =BJ7+(BK7*2350) -> 0 | BM18: =BL7+(BM7*2350) -> 0 | BO18: =BN7+(BO7*2350) -> 0 | BQ18: =BP7+(BQ7*2350) -> 0 | BS18: =BR7+(BS7*2350) -> 0 | BU18: =BT7+(BU7*2350) -> 0 | BW18: =BV7+(BW7*2350) -> 0 | BY18: =BX7+(BY7*2350) -> 0 | CA18: =BZ7+(CA7*2350) -> 0 | CC18: =CB7+(CC7*2350) -> 0 | CE18: =CD7+(CE7*2350) -> 0 | CG18: =CF7+(CG7*2350) -> 0
A19: EQUITY | C19: =B7+(C7*2350) -> 8011025 | E19: =D8+(E8*2350) -> 0 | G19: =F8+(G8*2350) -> 942000 | I19: =H8+(I8*2350) -> 0 | K19: =J8+(K8*2350) -> 1615000 | M19: =L8+(M8*2350) -> 1962000 | O19: =N8+(O8*2350) -> 0 | Q19: =P8+(Q8*2350) -> 0 | S19: =R8+(S8*2350) -> 0 | U19: =T8+(U8*2350) -> 0 | W19: =V8+(W8*2350) -> 0 | Y19: =X8+(Y8*2350) -> 0 | AA19: =Z8+(AA8*2350) -> 0 | AC19: =AB8+(AC8*2350) -> 0 | AE19: =AD8+(AE8*2350) -> 0 | AG19: =AF8+(AG8*2350) -> 0 | AI19: =AH8+(AI8*2350) -> 0 | AK19: =AJ8+(AK8*2350) -> 0 | AM19: =AL8+(AM8*2350) -> 0 | AO19: =AN8+(AO8*2350) -> 0 | AQ19: =AP8+(AQ8*2350) -> 0 | AS19: =AR8+(AS8*2350) -> 0 | AU19: =AT8+(AU8*2350) -> 0 | AW19: =AV8+(AW8*2350) -> 0 | AY19: =AX8+(AY8*2350) -> 0 | BA19: =AZ8+(BA8*2350) -> 0 | BC19: =BB8+(BC8*2350) -> 0 | BE19: =BD8+(BE8*2350) -> 0 | BG19: =BF8+(BG8*2350) -> 0 | BI19: =BH8+(BI8*2350) -> 0 | BK19: =BJ8+(BK8*2350) -> 0 | BM19: =BL8+(BM8*2350) -> 0 | BO19: =BN8+(BO8*2350) -> 0 | BQ19: =BP8+(BQ8*2350) -> 0 | BS19: =BR8+(BS8*2350) -> 0 | BU19: =BT8+(BU8*2350) -> 0 | BW19: =BV8+(BW8*2350) -> 0 | BY19: =BX8+(BY8*2350) -> 0 | CA19: =BZ8+(CA8*2350) -> 0 | CC19: =CB8+(CC8*2350) -> 0 | CE19: =CD8+(CE8*2350) -> 0 | CG19: =CF8+(CG8*2350) -> 0
A20: MPSA | C20: =B8+(C8*2350) -> 947050 | E20: =D9+(E9*2350) -> 1892250 | G20: =F9+(G9*2350) -> 824850 | I20: =H9+(I9*2350) -> 0 | K20: =J9+(K9*2350) -> 2873150 | M20: =L9+(M9*2350) -> 1220000 | O20: =N9+(O9*2350) -> 0 | Q20: =P9+(Q9*2350) -> 0 | S20: =R9+(S9*2350) -> 0 | U20: =T9+(U9*2350) -> 0 | W20: =V9+(W9*2350) -> 0 | Y20: =X9+(Y9*2350) -> 0 | AA20: =Z9+(AA9*2350) -> 0 | AC20: =AB9+(AC9*2350) -> 0 | AE20: =AD9+(AE9*2350) -> 0 | AG20: =AF9+(AG9*2350) -> 0 | AI20: =AH9+(AI9*2350) -> 0 | AK20: =AJ9+(AK9*2350) -> 0 | AM20: =AL9+(AM9*2350) -> 0 | AO20: =AN9+(AO9*2350) -> 0 | AQ20: =AP9+(AQ9*2350) -> 0 | AS20: =AR9+(AS9*2350) -> 0 | AU20: =AT9+(AU9*2350) -> 0 | AW20: =AV9+(AW9*2350) -> 0 | AY20: =AX9+(AY9*2350) -> 0 | BA20: =AZ9+(BA9*2350) -> 0 | BC20: =BB9+(BC9*2350) -> 0 | BE20: =BD9+(BE9*2350) -> 0 | BG20: =BF9+(BG9*2350) -> 0 | BI20: =BH9+(BI9*2350) -> 0 | BK20: =BJ9+(BK9*2350) -> 0 | BM20: =BL9+(BM9*2350) -> 0 | BO20: =BN9+(BO9*2350) -> 0 | BQ20: =BP9+(BQ9*2350) -> 0 | BS20: =BR9+(BS9*2350) -> 0 | BU20: =BT9+(BU9*2350) -> 0 | BW20: =BV9+(BW9*2350) -> 0 | BY20: =BX9+(BY9*2350) -> 0 | CA20: =BZ9+(CA9*2350) -> 0 | CC20: =CB9+(CC9*2350) -> 0 | CE20: =CD9+(CE9*2350) -> 0 | CG20: =CF9+(CG9*2350) -> 0
A21: RAWBANK | C21: =B9+(C9*2350) -> 1677950 | E21: =D10+(E10*2350) -> 0 | G21: =F10+(G10*2350) -> 0 | I21: =H10+(I10*2350) -> 0 | K21: =J10+(K10*2350) -> 0 | M21: =L10+(M10*2350) -> 0 | O21: =N10+(O10*2350) -> 0 | Q21: =P10+(Q10*2350) -> 0 | S21: =R10+(S10*2350) -> 0 | U21: =T10+(U10*2350) -> 0 | W21: =V10+(W10*2350) -> 0 | Y21: =X10+(Y10*2350) -> 0 | AA21: =Z10+(AA10*2350) -> 0 | AC21: =AB10+(AC10*2350) -> 0 | AE21: =AD10+(AE10*2350) -> 0 | AG21: =AF10+(AG10*2350) -> 0 | AI21: =AH10+(AI10*2350) -> 0 | AK21: =AJ10+(AK10*2350) -> 0 | AM21: =AL10+(AM10*2350) -> 0 | AO21: =AN10+(AO10*2350) -> 0 | AQ21: =AP10+(AQ10*2350) -> 0 | AS21: =AR10+(AS10*2350) -> 0 | AU21: =AT10+(AU10*2350) -> 0 | AW21: =AV10+(AW10*2350) -> 0 | AY21: =AX10+(AY10*2350) -> 0 | BA21: =AZ10+(BA10*2350) -> 0 | BC21: =BB10+(BC10*2350) -> 0 | BE21: =BD10+(BE10*2350) -> 0 | BG21: =BF10+(BG10*2350) -> 0 | BI21: =BH10+(BI10*2350) -> 0 | BK21: =BJ10+(BK10*2350) -> 0 | BM21: =BL10+(BM10*2350) -> 0 | BO21: =BN10+(BO10*2350) -> 0 | BQ21: =BP10+(BQ10*2350) -> 0 | BS21: =BR10+(BS10*2350) -> 0 | BU21: =BT10+(BU10*2350) -> 0 | BW21: =BV10+(BW10*2350) -> 0 | BY21: =BX10+(BY10*2350) -> 0 | CA21: =BZ10+(CA10*2350) -> 0 | CC21: =CB10+(CC10*2350) -> 0 | CE21: =CD10+(CE10*2350) -> 0 | CG21: =CF10+(CG10*2350) -> 0
A22: TMB | C22: =B10+(C10*2350) -> 0 | E22: =D10+(E10*2350) -> 0 | G22: =F10+(G10*2350) -> 0 | I22: =H10+(I10*2350) -> 0 | K22: =J10+(K10*2350) -> 0 | M22: =L10+(M10*2350) -> 0 | O22: =N10+(O10*2350) -> 0 | Q22: =P10+(Q10*2350) -> 0 | S22: =R10+(S10*2350) -> 0 | U22: =T10+(U10*2350) -> 0 | W22: =V10+(W10*2350) -> 0 | Y22: =X10+(Y10*2350) -> 0 | AA22: =Z10+(AA10*2350) -> 0 | AC22: =AB10+(AC10*2350) -> 0 | AE22: =AD10+(AE10*2350) -> 0 | AG22: =AF10+(AG10*2350) -> 0 | AI22: =AH10+(AI10*2350) -> 0 | AK22: =AJ10+(AK10*2350) -> 0 | AM22: =AL10+(AM10*2350) -> 0 | AO22: =AN10+(AO10*2350) -> 0 | AQ22: =AP10+(AQ10*2350) -> 0 | AS22: =AR10+(AS10*2350) -> 0 | AU22: =AT10+(AU10*2350) -> 0 | AW22: =AV10+(AW10*2350) -> 0 | AY22: =AX10+(AY10*2350) -> 0 | BA22: =AZ10+(BA10*2350) -> 0 | BC22: =BB10+(BC10*2350) -> 0 | BE22: =BD10+(BE10*2350) -> 0 | BG22: =BF10+(BG10*2350) -> 0 | BI22: =BH10+(BI10*2350) -> 0 | BK22: =BJ10+(BK10*2350) -> 0 | BM22: =BL10+(BM10*2350) -> 0 | BO22: =BN10+(BO10*2350) -> 0 | BQ22: =BP10+(BQ10*2350) -> 0 | BS22: =BR10+(BS10*2350) -> 0 | BU22: =BT10+(BU10*2350) -> 0 | BW22: =BV10+(BW10*2350) -> 0 | BY22: =BX10+(BY10*2350) -> 0 | CA22: =BZ10+(CA10*2350) -> 0 | CC22: =CB10+(CC10*2350) -> 0 | CE22: =CD10+(CE10*2350) -> 0 | CG22: =CF10+(CG10*2350) -> 0
